A chaque fois  que je lance mon docker compose, les connexions ne se font pas.

Cela fait 1 semaine que je suis dessus, et je n'arrive pas à trouver d'ou vient le probleme.
Quand je lance des containers par image, la connexion se fait trés bien.
J'utilise les mêmes parametres networks que dans le docker compose.

J'ai donc choisi de lancer les containers individuellement et recuperer les logs. 
Dans le fichier setup.sh, j'ai indiqué les commandes pour lancer les containers individuellement.


Voici ce qui s'affiche pour les containers de test quand je lance docker compose:


Traceback (most recent call last):
my_autorization_test |   File "/usr/local/lib/python3.6/dist-packages/urllib3/connection.py", line 175, in _new_conn
my_autorization_test |     (self._dns_host, self.port), self.timeout, **extra_kw
my_autorization_test |   File "/usr/local/lib/python3.6/dist-packages/urllib3/util/connection.py", line 95, in create_connection
my_autorization_test |     raise err
my_autorization_test |   File "/usr/local/lib/python3.6/dist-packages/urllib3/util/connection.py", line 85, in create_connection
my_autorization_test |     sock.connect(sa)
my_autorization_test | ConnectionRefusedError: [Errno 111] Connection refused
rllib3.exceptions.NewConnectionError: <urllib3.connection.HTTPConnection object at 0x7f23615bdef0>: 
Failed to establish a new connection: [Errno 111] Connection refused